ERROR:root:Exception occurred while running the server
Traceback (most recent call last):
  File "run_server.py", line 12, in <module>
  File "django\core\management\__init__.py", line 442, in execute_from_command_line
    utility.execute()
  File "django\core\management\__init__.py", line 436, in execute
    self.fetch_command(subcommand).run_from_argv(self.argv)
  File "django\core\management\base.py", line 413, in run_from_argv
    self.execute(*args, **cmd_options)
  File "django\core\management\commands\runserver.py", line 74, in execute
    super().execute(*args, **options)
  File "django\core\management\base.py", line 459, in execute
    output = self.handle(*args, **options)
             ^^^^^^^^^^^^^^^^^^^^^^^^^^^^^
  File "django\core\management\commands\runserver.py", line 111, in handle
    self.run(**options)
  File "django\core\management\commands\runserver.py", line 118, in run
    autoreload.run_with_reloader(self.inner_run, **options)
  File "django\utils\autoreload.py", line 673, in run_with_reloader
    exit_code = restart_with_reloader()
                ^^^^^^^^^^^^^^^^^^^^^^^
  File "PyInstaller\hooks\rthooks\pyi_rth_django.py", line 24, in _restart_with_reloader
  File "django\utils\autoreload.py", line 272, in restart_with_reloader
    args = get_child_arguments()
           ^^^^^^^^^^^^^^^^^^^^^
  File "django\utils\autoreload.py", line 229, in get_child_arguments
    py_script = Path(sys.argv[0])
                     ~~~~~~~~^^^
IndexError: list index out of range
